Workbook

Sheet PC
E4: Tên | F4: Deadline
D5: GIẢ ĐỊNH DOANH THU, DỰ TOÁN BÁO CÁO THU NHẬP | E5: Dương | F5: hạn cuối hết thứ 2 (26/10)
E6: Tú
D7: DỰ TOÁN BCĐKT + BCLCTT | E7: Phụng | F7: hạn cuối 22h thứ 4 (28/10)
E8: Trâm
D9: THỜI GIAN HOÀN VỐN, NPV, IRR | E9: Tuyền

Sheet Giả định
B3: Tên dự án | D3: RE-FILL
B4: Thành viên nhóm | D4: 1. Đinh Ngọc Thùy Dương
D5: 2. Mai Thanh Cẩm Tú
D6: 3. Hồ Thị Mỹ Trâm
D7: 4. Nguyễn Thị Kim Tuyền
D8: 5. Hồ Kim Phụng
B9: Mô tả chung về dự án
B14: STT | D14: Giả định | E14: Giải thích
B15: 1 | C15: Trạm RE-FILL | D15: Số lượng 2 Diện tích: 3–4 m² | I15: Giá thị trường Phân khúc bình dân | J15: Giá bán ước tính/250ml | K15: Giá bán ước tính/100ml | L15: Giá bán ước tính/500ml
B16: 2 | C16: Mặt bằng | D16: Tại Liên Chiểu | H16: Dầu gội | I16: Dầu gội cao bồ kết Thorakao 250ml: 48.000 Dầu gội Dược liệu Nguyên Xuân Nâu 250ml: Giá khoảng 70.000đ – 79.000đ Dầu gội Clear / Pantene / Head & Shoulders (330ml - 380ml): Mức giá dao động từ 85.000đ – 115.000đ | J16: =48000*(1-20%) -> 38400 | K16: =(J16/250)*100 -> 15360 | L16: =(J16/250)*500 -> 76800 | M16: link | N16: link
B17: 3 | D17: Tại Ngũ Hành Sơn | H17: Sữa tắm | I17: Sữa tắm Lifebuoy chăm sóc da chai 250g: 58.000 Sữa tắm gội Lactacyd Baby Extra Milky 250ml: 100.000 | J17: =58000*(1-20%) -> 46400 | K17: =(J17/250)*100 -> 18560 | L17: =(J17/250)*500 -> 92800 | M17: link | N17: link
B18: 4 | C18: Công suất làm việc máy | D18: 8h-21h | H18: Nước rửa chén | I18: Nước rửa chén hương Chanh Sunlight 400g: 26.000 Nước rửa chén Mỹ Hảo 200ml: 18.000 | J18: =(18000/200)*250*80% -> 18000 | K18: =(J18/250)*100 -> 7200 | L18: =(J18/250)*500 -> 36000 | M18: link | N18: link
B19: 5 | C19: Nhân sự | D19: Số lượng: 5 - Nguyễn Thị Kim Tuyền + Quản lý chung- giám sát vận hành tài chính - Đinh Ngọc Thùy Dương + Bộ phận chuỗi cung ứng + Nhập hàng BONNY, điều phối sản phẩm nạp ra 2 trạm, kiểm tra chất lượng, vệ sinh, bảo trì máy chiết rót; Phụ trách trạm 1: bật máy chiết rót lúc 8:00, tắt máy và vệ sinh lúc 21:00, bổ sung và kiểm tra dung dịch, hỗ trợ khách, giao hàng online cho trạm 1. giao hàng online cho trạm 1. - Hồ Kim Phụng + Bộ phận Tài chính- kế toán + Thu–chi, đối soát doanh thu, theo dõi tồn kho và giá vốn, kê khai thuế, chấm công, tính lương nhân viên, lập báo cáo tài chính. - Hồ Thị Mỹ Trâm + Bộ phận Marketing + Tìm kiếm và phát triển khách hàng + Chạy quảng cáo Facebook/TikTok, vận hành chương trình khuyến mãi, quản lý fanpage, theo dõi phản hồi và giải đáp thắc mắc của khách hàng trên các kênh trực tuyến. Đồng thời, Trâm tiếp nhận và xác nhận thông tin đơn hàng, sau đó phối hợp với Dương hoặc Tú để chuẩn bị và giao hàng. - Mai Thanh Cẩm Tú + Bộ phận kinh doanh + Khảo sát, thương lượng địa điểm (ký túc xá, chung cư, khu dân cư), phụ trách trạm 2: bật máy chiết rót lúc 8:00, tắt máy và vệ sinh lúc 21:00, bổ sung và kiểm tra dung dịch, hỗ trợ khách, giao hàng online cho trạm 2.
B20: 6 | C20: Lương Nhân sự | D20: - Đinh Ngọc Thùy Dương Mức lương= lương/ tháng+ chi phí bảo hiểm, kinh phí công đoàn(23,5%) = 8.645.000 đ - Mai Thanh Cẩm Tú Mức lương= lương/ tháng+ chi phí bảo hiểm, kinh phí công đoàn(23,5%)= 8.027.500 đ - Hồ Thị Mỹ Trâm Mức lương= lương/ tháng+ chi phí bảo hiểm, kinh phí công đoàn(23,5%)= 8.027.500 đ - Nguyễn Thị Kim Tuyền Mức lương= lương/ tháng+ chi phí bảo hiểm, kinh phí công đoàn(23,5%)= 12.350.000 đ - Hồ Kim Phụng Mức lương= lương/ tháng+ chi phí bảo hiểm, kinh phí công đoàn(23,5%)= 8.645.000 đ
B21: 7 | C21: Giá vốn | D21: Dầu gội Bonny: 38.500đ/ 1 lít Sữa tắm Bonny: 38.500đ/ 1 lít Nước rửa chén Bonny: 25.800đ/ 1 lít
B22: 8 | C22: Giá vốn hàng bán tăng mỗi năm | D22: Giá vốn mỗi lít được giả định tăng 3% mỗi năm nhằm phản ánh sự gia tăng của giá nguyên liệu đầu vào do tác động của lạm phát. Mức tăng này được áp dụng trên giá vốn của năm trước, kết hợp với sản lượng nạp dự kiến tăng qua từng năm để xác định tổng chi phí nguyên liệu trong kỳ. Theo số liệu, CPI bình quân của Việt Nam giai đoạn 2016–2025 ở mức khoảng 3,09%/năm. Giả định tăng giá vốn 3%/năm được lựa chọn làm cơ sở dự báo, phù hợp với xu hướng biến động giá cả trong dài hạn. | E22: link
B23: 9 | C23: Hao hụt chiết rót | D23: Giả định tỷ lệ hao hụt nguyên liệu ở mức 3% giá vốn nhằm dự phòng lượng dung dịch thất thoát.
B24: 10 | C24: Hàng tồn kho | D24: Nhập hàng theo nhu cầu bán, bổ sung thường xuyên và không còn hàng tồn kho đáng kể vào cuối mỗi kỳ. RE-FILL dự kiến triển khai bán hàng trực tiếp tại trạm refill kết hợp bán hàng online thông qua các kênh trực tuyến. Đối với hoạt động tại trạm, doanh nghiệp chủ động bổ sung sản phẩm định kỳ dựa trên nhu cầu tiêu thụ dự kiến. Đối với kênh online, doanh nghiệp tiếp nhận đơn đặt hàng, tổng hợp nhu cầu và tổ chức chuẩn bị hàng hóa theo đơn nhằm hạn chế lượng hàng lưu kho.
B25: 11 | C25: Giá bán | D25: Giá thị trường của dầu gội (dao động từ 48.000 đến 115.000đ/250ml), sữa tắm (dao động từ 58.000 đến 100.000đ/250ml), nước rửa chén(dao động từ 18.000 đến 26.000đ/250ml), dự án giả định mức giá refill thấp hơn 20% so với giá tham chiếu nhằm tạo lợi thế cạnh tranh, tiết kiệm chi phí cho khách hàng và khuyến khích tái sử dụng chai đựng. Trong các năm tiếp theo, giá bán được giả định tăng 3%/năm để bù đắp mức tăng chi phí đầu vào do lạm phát, đồng thời duy trì tính cạnh tranh của sản phẩm. Giá refill(đã làm tròn): Dầu gội Bonny: (15.000 đ/100ml, 38.000 đ/250ml, 77.000 đ/ 500ml) Sữa tắm Bonny: (19.000 đ/100ml, 46.000 đ/250ml, 93.000 đ/ 500ml) Nước rửa chén Bonny:( 7.000 đ/100ml, 18.000 đ/250ml, 36.000 đ/ 500ml)
B26: 12 | C26: Khuyến mãi khai trương trạm | D26: Triển khai ở tháng đầu tiên, giảm 10% cho tổng đơn hàng Ngân sách khuyến mãi cho cả 2 trạm: 2.000.000 đ
B27: 13 | C27: Khách hàng | D27: Tháng 1: tổng 600 khách hàng cho cả 2 trạm Tháng 2 đến tháng 12: Tăng lên 650 khách hàng cho cả 2 trạm Tăng trưởng khách hàng mỗi năm: 10%
B28: 14 | C28: Doanh thu theo tháng - năm 1 | D28: Giả định: - Số khách hàng trung bình mỗi trạm: 300 người/ 1 trạm - Mỗi khách nạp 250ml mỗi sản phẩm/ 1 tháng - Tổng sản lượng nạp: 250 ml x 3 = 750 ml + Tháng 1 600 khách hàng 2 trạm Doanh thu dầu gội = số lượng nạp x số lượng khách hàng x giá bán= 22.800.000 đ Doanh thu nước rửa chén = số lượng nạp x số lượng khách hàng x giá bán= 10.800.000 đ Doanh thu sữa tắm = số lượng nạp x số lượng khách hàng x giá bán= 27.600.000 đ Tổng doanh thu tháng 1 năm 1= Doanh thu dầu gội + doanh thu nước rửa chén + doanh thu sữa tắm=61.200.000 đ + Tháng 2-12 650 khách hàng 2 trạm Doanh thu dầu gội(tháng) = số lượng nạp x số lượng khách hàng x giá bán= 24.700.000 đ Doanh thu nước rửa chén(tháng) = số lượng nạp x số lượng khách hàng x giá bán= 11.700.000 đ Doanh thu sữa tắm(tháng) = số lượng nạp x số lượng khách hàng x giá bán= 29.900.000 đ Tổng doanh thu tháng 2-12 năm 1(tháng)= Doanh thu dầu gội + doanh thu nước rửa chén + doanh thu sữa tắm=66.300.000 đ
B29: 15 | C29: Doanh thu tăng trưởng hàng năm | D29: Doanh thu tăng 13%/ năm (tăng trưởng khách hàng 10% và giá bán tăng 3%)
B30: 16 | C30: Thuế TNDN | D30: 15% (doanh nghiệp có tổng doanh thu năm không quá 3 tỷ đồng). | E30: Điều 10, Luật Thuế Thu nhập doanh nghiệp 2025 (Luật số 67/2025/QH15)
B31: 17 | C31: Tài sản cố định | D31: Trang thiết bị nguyên giá: 91.182.000đ khấu hao đường thẳng 5 năm | E31: Gồm 2 máy chiết rót, 2 máy POS và dụng cụ trạm ( sheet Giả định chi phí). Không mua thêm TSCĐ trong 5 năm
B33: 18 | C33: Hàng tồn kho | D33: Tồn kho bình quân 5 ngày giá vốn; phải thu 2 ngày doanh thu; phải trả nhà cung cấp 15 ngày | E33: Nhập hàng theo nhu cầu nên tồn kho thấp
B34: 19 | C34: Vốn đầu tư ban đầu | D34: Đầu tư ban đầu 91.832.000đ; góp vốn chủ sở hữu: 250 triệu (Năm 0), 100 triệu (Năm 2), 50 triệu (Năm 3) | E34: Không vay nợ. Vốn góp bù lỗ để tiền mặt không âm.

Sheet Giả định doanh thu
B2: SỐ LƯỢNG KHÁCH HÀNG (CẢ 2 TRẠM)
B3: Chỉ tiêu | C3: Số lượng | D3: Giải thích
B4: Số khách hàng tháng 1 | C4: 600 | D4: Khách mở đầu, khuyến mãi khai trương, quảng cáo thu hút khách hàng
B5: Số khách hàng tháng 2–12 | C5: 650
B6: Tăng trưởng khách hàng mỗi năm | C6: 0.1
B7: Giá bán | C7: 0.03 | D7: Giá bán tăng 3% qua mỗi năm
B8: Doanh thu tăng trưởng | C8: 0.13 | D8: Doanh thu tăng 13% qua mỗi năm (khách hàng tăng 10% và giá bán tăng 3%)
B9: Khách bình quân mỗi trạm (tháng 1) | C9: 300 | D9: khách/trạm/tháng
B10: Khách bình quân mỗi trạm (tháng 2–12) | C10: 325 | D10: khách/trạm/tháng
B13: BẢNG GIÁ SẢN PHẨM – NĂM 1
B14: Sản phẩm | C14: Giá /100ml | D14: Giá /250ml | E14: Giá /500ml
B15: Dầu gội BONNY | C15: 15000 | D15: 38000 | E15: 77000
B16: Sữa tắm BONNY | C16: 19000 | D16: 46000 | E16: 93000
B17: Nước rửa chén BONNY | C17: 7000 | D17: =(18000/200)*250*80% -> 18000 | E17: 36000
B20: LƯỢNG NẠP VÀ DOANH THU BÌNH QUÂN MỖI KHÁCH MỖI THÁNG
B21: Danh mục | C21: Lượng nạp (ml/khách/tháng) | D21: Tỷ lệ sản lượng | E21: Doanh thu/khách/ tháng (đ) | F21: Giá vốn/khách (đ) | G21: Giá vốn/lít
B22: Dầu gội | C22: 250 | D22: 33.3% | E22: =D15 -> 38000 | F22: 9625 | G22: ='Giả định chi phí'!L24 -> 38500
B23: Sữa tắm | C23: 250 | D23: 33.3% | E23: =D16 -> 46000 | F23: 9625 | G23: ='Giả định chi phí'!L25 -> 38500
B24: Nước rửa chén | C24: 250 | D24: 33.3% | E24: =D17 -> 18000 | F24: 7125 | G24: ='Giả định chi phí'!L26 -> 25800
B25: Tổng lượng nạp | C25: 750 | D25: 100.0% | E25: =SUM(E22:E24) -> 102000 | F25: =SUM(F22:F24) -> 26375
B26: Tỷ lệ giá vốn / doanh thu | F26: =(F25/E25) -> 0.25857843
B29: CHƯƠNG TRÌNH KHUYẾN MÃI
B30: THÁNG 1- NĂM 1 | C30: 2000000 | D30: Giảm 10%/ tổng giá trị đơn hàng
B33: DOANH THU VÀ GIÁ VỐN THEO THÁNG – NĂM 1
B34: Chỉ tiêu | C34: Tháng 1 | D34: Tháng 2 | E34: Tháng 3 | F34: Tháng 4 | G34: Tháng 5 | H34: Tháng 6 | I34: Tháng 7 | J34: Tháng 8 | K34: Tháng 9 | L34: Tháng 10 | M34: Tháng 11 | N34: Tháng 12 | O34: Năm 1
B35: Số lượng khách hàng | C35: 600 | D35: 650 | E35: 650 | F35: 650 | G35: 650 | H35: 650 | I35: 650 | J35: 650 | K35: 650 | L35: 650 | M35: 650 | N35: 650 | O35: =SUM(C35:N35) -> 7750
B36: Doanh thu dầu gội | C36: =C35*$E$22 -> 22800000 | D36: =D35*$E$22 -> 24700000 | E36: =E35*$E$22 -> 24700000 | F36: =F35*$E$22 -> 24700000 | G36: =G35*$E$22 -> 24700000 | H36: =H35*$E$22 -> 24700000 | I36: =I35*$E$22 -> 24700000 | J36: =J35*$E$22 -> 24700000 | ... N36: =N35*$E$22 -> 24700000 | O36: =SUM(C36:N36) -> 294500000
B37: Doanh thu sữa tắm | C37: =C35*$E$23 -> 27600000 | D37: =D35*$E$23 -> 29900000 | E37: =E35*$E$23 -> 29900000 | F37: =F35*$E$23 -> 29900000 | G37: =G35*$E$23 -> 29900000 | H37: =H35*$E$23 -> 29900000 | I37: =I35*$E$23 -> 29900000 | J37: =J35*$E$23 -> 29900000 | ... N37: =N35*$E$23 -> 29900000 | O37: =SUM(C37:N37) -> 356500000
B38: Doanh thu nước rửa chén | C38: =C35*$E$24 -> 10800000 | D38: =D35*$E$24 -> 11700000 | E38: =E35*$E$24 -> 11700000 | F38: =F35*$E$24 -> 11700000 | G38: =G35*$E$24 -> 11700000 | H38: =H35*$E$24 -> 11700000 | I38: =I35*$E$24 -> 11700000 | J38: =J35*$E$24 -> 11700000 | ... N38: =N35*$E$24 -> 11700000 | O38: =SUM(C38:N38) -> 139500000
B39: Tổng doanh thu | C39: =SUM(C36:C38) -> 61200000 | D39: =SUM(D36:D38) -> 66300000 | E39: =SUM(E36:E38) -> 66300000 | F39: =SUM(F36:F38) -> 66300000 | G39: =SUM(G36:G38) -> 66300000 | H39: =SUM(H36:H38) -> 66300000 | I39: =SUM(I36:I38) -> 66300000 | J39: =SUM(J36:J38) -> 66300000 | ... O39: =SUM(O36:O38) -> 790500000
B40: Khuyến mãi khai trương (giảm trừ) | C40: 2000000 | D40: - | E40: - | F40: - | G40: - | H40: - | I40: - | J40: - | K40: - | L40: - | M40: - | N40: - | O40: -
B41: Doanh thu thuần | C41: =C39-C40 -> 59200000 | D41: =D39 -> 66300000 | E41: =E39 -> 66300000 | F41: =F39 -> 66300000 | G41: =G39 -> 66300000 | H41: =H39 -> 66300000 | I41: =I39 -> 66300000 | J41: =J39 -> 66300000 | K41: =K39 -> 66300000 | ... O41: =O39 -> 790500000
B42: Sản lượng dầu gội (lít) | C42: =(C35*$C$22)/1000 -> 150 | D42: =(D35*$C$22)/1000 -> 162.5 | E42: =(E35*$C$22)/1000 -> 162.5 | F42: =(F35*$C$22)/1000 -> 162.5 | G42: =(G35*$C$22)/1000 -> 162.5 | H42: =(H35*$C$22)/1000 -> 162.5 | I42: =(I35*$C$22)/1000 -> 162.5 | J42: =(J35*$C$22)/1000 -> 162.5 | ... N42: =(N35*$C$22)/1000 -> 162.5 | O42: =SUM(C42:N42) -> 1937.5
B43: Sản lượng sữa tắm (lít) | C43: =(C35*$C$23)/1000 -> 150 | D43: =(D35*$C$23)/1000 -> 162.5 | E43: =(E35*$C$23)/1000 -> 162.5 | F43: =(F35*$C$23)/1000 -> 162.5 | G43: =(G35*$C$23)/1000 -> 162.5 | H43: =(H35*$C$23)/1000 -> 162.5 | I43: =(I35*$C$23)/1000 -> 162.5 | J43: =(J35*$C$23)/1000 -> 162.5 | ... N43: =(N35*$C$23)/1000 -> 162.5 | O43: =SUM(C43:N43) -> 1937.5
B44: Sản lượng nước rửa chén (lít) | C44: =(C35*$C$24)/1000 -> 150 | D44: =(D35*$C$24)/1000 -> 162.5 | E44: =(E35*$C$24)/1000 -> 162.5 | F44: =(F35*$C$24)/1000 -> 162.5 | G44: =(G35*$C$24)/1000 -> 162.5 | H44: =(H35*$C$24)/1000 -> 162.5 | I44: =(I35*$C$24)/1000 -> 162.5 | J44: =(J35*$C$24)/1000 -> 162.5 | ... N44: =(N35*$C$24)/1000 -> 162.5 | O44: =SUM(C44:N44) -> 1937.5
B45: Giá vốn dầu gội | C45: =C42*$G$22 -> 5775000 | D45: =D42*$G$22 -> 6256250 | E45: =E42*$G$22 -> 6256250 | F45: =F42*$G$22 -> 6256250 | G45: =G42*$G$22 -> 6256250 | H45: =H42*$G$22 -> 6256250 | I45: =I42*$G$22 -> 6256250 | J45: =J42*$G$22 -> 6256250 | ... O45: =O42*$G$22 -> 74593750
B46: Giá vốn sữa tắm | C46: =C43*$G$23 -> 5775000 | D46: =D43*$G$23 -> 6256250 | E46: =E43*$G$23 -> 6256250 | F46: =F43*$G$23 -> 6256250 | G46: =G43*$G$23 -> 6256250 | H46: =H43*$G$23 -> 6256250 | I46: =I43*$G$23 -> 6256250 | J46: =J43*$G$23 -> 6256250 | ... O46: =O43*$G$23 -> 74593750
B47: Giá vốn nước rửa chén | C47: =C44*$G$24 -> 3870000 | D47: =D44*$G$24 -> 4192500 | E47: =E44*$G$24 -> 4192500 | F47: =F44*$G$24 -> 4192500 | G47: =G44*$G$24 -> 4192500 | H47: =H44*$G$24 -> 4192500 | I47: =I44*$G$24 -> 4192500 | J47: =J44*$G$24 -> 4192500 | ... O47: =O44*$G$24 -> 49987500
B48: Tổng giá vốn hàng bán | C48: =SUM(C45:C47) -> 15420000 | D48: =SUM(D45:D47) -> 16705000 | E48: =SUM(E45:E47) -> 16705000 | F48: =SUM(F45:F47) -> 16705000 | G48: =SUM(G45:G47) -> 16705000 | H48: =SUM(H45:H47) -> 16705000 | I48: =SUM(I45:I47) -> 16705000 | J48: =SUM(J45:J47) -> 16705000 | ... O48: =SUM(O45:O47) -> 199175000
B51: DOANH THU VÀ GIÁ VỐN THEO NĂM
...

Sheet Giả định chi phí
B3: Chi phí lương nhân viên theo tháng
B5: Nhân viên | C5: Vị trí và nhiệm vụ | E5: Mức lương/ tháng | F5: Tổng chi phí/tháng | G5: (đã bao gồm (BH + KPCĐ 23,5%)
B6: Nguyễn Thị Kim Tuyền | C6: Quản lý chung / Giám sát vận hành & Tài chính | E6: 10000000 | F6: =E6*1.235 -> 12350000
B7: Đinh Ngọc Thùy Dương | C7: Bộ phận chuỗi cung ứng: Bộ phận chuỗi cung ứng Nhập hàng BONNY, điều phối sản phẩm nạp ra 2 trạm, kiểm tra chất lượng, vệ sinh, bảo trì máy chiết rót; Phụ trách trạm 1: bật máy chiết rót lúc 8:00, tắt máy và vệ sinh lúc 21:00, bổ sung và kiểm tra dung dịch hỗ trợ khách, giao hàng online cho trạm 1 | E7: 7000000 | F7: =E7*1.235 -> 8645000
B8: Hồ Kim Phụng | C8: Bộ phận Tài chính- kế toán: Thu–chi, đối soát doanh thu, theo dõi tồn kho và giá vốn, kê khai thuế, chấm công, tính lương nhân viên, lập báo cáo tài chính. | E8: 7000000 | F8: =E8*1.235 -> 8645000
B9: Hồ Thị Mỹ Trâm | C9: Bộ phận Marketing: Tìm kiếm và phát triển khách hàng Chạy quảng cáo Facebook/TikTok, vận hành chương trình khuyến mãi, quản lý fanpage, theo dõi phản hồi và giải đáp thắc mắc của khách hàng trên các kênh trực tuyến. Đồng thời, Trâm tiếp nhận và xác nhận thông tin đơn hàng, sau đó phối hợp với Dương và Tú để chuẩn bị và giao hàng. | E9: 6500000 | F9: =E9*1.235 -> 8027500
B10: Mai Thanh Cẩm Tú | C10: Bộ phận kinh doanh: Khảo sát, thương lượng địa điểm (ký túc xá, chung cư, khu dân cư), phụ trách trạm 2: bật máy chiết rót lúc 8:00, tắt máy và vệ sinh lúc 21:00, bổ sung và kiểm tra dung dịch, hỗ trợ khách, giao hàng online cho trạm 2. | E10: 6500000 | F10: =E10*1.235 -> 8027500
B11: Tổng | E11: =SUM(E6:E10) -> 37000000 | F11: =SUM(F6:F10) -> 45695000
B14: Chi phí pháp lý quản lý doanh nghiệp
B15: STT | C15: Khoản mục | E15: Năm 0 | F15: Link (nguồn)
B16: 1 | C16: Lệ phí đăng ký thành lập doanh nghiệp (Giấy phép KD) | E16: 50000 | F16: Link
B17: 2 | C17: Lệ phí công bố thông tin đăng ký doanh nghiệp | E17: 100000 | F17: Link
B18: Tổng | E18: =E16+E17 -> 150000
B21: Chi phí trang thiết bị
B22: STT | C22: Khoản mục | D22: Đơn vị | E22: Đơn giá | F22: Số lượng | G22: Thành tiền | H22: Link (nguồn) | J22: CHI PHÍ SẢN PHẨM NẠP- THÁNG 1
B23: 1 | C23: Máy chiết dung dịch tự động PUKUI | D23: Máy | E23: 34350000 | F23: 2 | G23: =E23*F23 -> 68700000 | H23: Link tham khảo | I23: Chưa tính chi phí vận chuyển + Thuế | J23: STT | K23: Khoản mục | L23: Đơn giá | M23: Đơn vị | N23: Số lượng | O23: Thành tiền | P23: Link(nguồn)
B24: 2 | C24: Máy POS bán hàng cảm ứng 2 màn hình | D24: Máy | E24: 10600000 | F24: 2 | G24: =E24*F24 -> 21200000 | H24: Link tham khảo | J24: 1 | K24: Dầu gội BONNY | L24: 38500 | M24: Lít | N24: 150 | O24: =L24*N24 -> 5775000 | P24: Link
B25: 3 | C25: Túi đựng dung dịch có nắp vặn 3L ( Bao bì đóng gói đơn hàng online ) | D25: Túi | E25: 19000 | F25: 6 | G25: =E25*F25 -> 114000 | H25: Link tham khảo | J25: 2 | K25: Sữa tắm BONNY | L25: 38500 | M25: Lít | N25: 150 | O25: =L25*N25 -> 5775000 | P25: Link
B26: 4 | C26: Decal logo RE-FILL, nhãn dán 3 loại sản phẩm và hướng dẫn sử dụng | D26: Bộ | E26: 150000 | F26: 2 | G26: =E26*F26 -> 300000 | H26: Link tham khảo | J26: 3 | K26: Nước rửa chén BONNY | L26: 25800 | M26: Lít | N26: 150 | O26: =L26*N26 -> 3870000 | P26: Link
B27: 5 | C27: Bảng mica nhận diện thương hiệu RE-FILL 30 × 40 cm | D27: Cái | E27: 250000 | F27: 2 | G27: =E27*F27 -> 500000 | H27: Link tham khảo | J27: 4 | K27: Chi phí vận chuyển dầu gội, sữa tắm, nước rửa chén | L27: 0 | O27: =L27*N27 -> 0
B28: 6 | C28: Bảng menu sản phẩm ( In decal bồi formex 3mm-5mm.) | D28: Cái | E28: 70000 | F28: 2 | G28: =E28*F28 -> 140000 | H28: Link tham khảo | J28: 5 | K28: Phễu chiết rót lọc dung dịch | L28: 36000 | M28: Cái | N28: 3 | O28: =L28*N28 -> 108000 | P28: Link
B29: 7 | C29: Dụng cụ làm sạch chai đựng dung dịch của khách hàng | D29: Bộ | E29: 86000 | F29: 2 | G29: =E29*F29 -> 172000 | H29: Link tham khảo | J29: Tổng | O29: =SUM(O24:O28) -> 15528000
B30: 8 | C30: Ca đong có chia vạch (1000ml) | D30: Cái | E30: 28000 | F30: 2 | G30: =E30*F30 -> 56000 | H30: Link tham khảo
B31: Tổng | G31: =SUM(G22:G30) -> 91182000 | M31: 46065 | N31: 162.5 | O31: =N31*L24*2+N31*L26 -> 16705000
B35: Chi phí cố định ( áp dụng cho 2 cơ sở)
B36: STT | C36: Khoản mục | E36: Năm 1(tính theo tháng) | F36: Năm 1 | G36: Năm 2 | H36: Năm 3 | I36: Năm 4 | J36: Năm 5 | K36: Link (nguồn)
B37: A | C37: Chi phí nhân sự
B38: 1 | C38: Lương quản lý chung | E38: =F6 -> 12350000 | F38: =E38*12 -> 1.482e+08 | G38: =F38*(1+4%) -> 1.54128e+08 | H38: =G38*(1+4%) -> 1.6029312e+08 | I38: =H38*(1+4%) -> 1.6670484e+08 | J38: =I38*(1+4%) -> 1.7337304e+08
B39: 2 | C39: Lương trưởng bộ phận Sản xuất & Vận hành | E39: =F7 -> 8645000 | F39: =E39*12 -> 103740000 | G39: =F39*(1+4%) -> 107889600 | H39: =G39*(1+4%) -> 112205184 | I39: =H39*(1+4%) -> 1.1669339e+08 | J39: =I39*(1+4%) -> 1.2136113e+08
B40: 3 | C40: Lương trưởng bộ phận Tài chính – Kế toán | E40: =F8 -> 8645000 | F40: =E40*12 -> 103740000 | G40: =F40*(1+4%) -> 107889600 | H40: =G40*(1+4%) -> 112205184 | I40: =H40*(1+4%) -> 1.1669339e+08 | J40: =I40*(1+4%) -> 1.2136113e+08
B41: 4 | C41: Lương trưởng bộ phận Marketing | E41: =F9 -> 8027500 | F41: =E41*12 -> 96330000 | G41: =F41*(1+4%) -> 1.001832e+08 | H41: =G41*(1+4%) -> 1.0419053e+08 | I41: =H41*(1+4%) -> 1.0835815e+08 | J41: =I41*(1+4%) -> 1.1269248e+08
B42: 5 | C42: Lương trưởng bộ phận Kinh doanh | E42: =F10 -> 8027500 | F42: =E42*12 -> 96330000 | G42: =F42*(1+4%) -> 1.001832e+08 | H42: =G42*(1+4%) -> 1.0419053e+08 | I42: =H42*(1+4%) -> 1.0835815e+08 | J42: =I42*(1+4%) -> 1.1269248e+08
B43: B | C43: Chi phí mặt bằng (2 cơ sở)
B44: 6 | C44: Thuê mặt bằng kinh doanh và lưu kho | E44: =6000000*2 -> 12000000 | F44: =E44*12 -> 144000000 | G44: =F44*(1+5%) -> 151200000 | H44: =G44*(1+5%) -> 158760000 | I44: =H44*(1+5%) -> 166698000 | J44: =I44*(1+5%) -> 175032900
B45: C | C45: Chi phí vận hành cố định | O45: BẢNG TỔNG HỢP
B46: 7 | C46: Điện cố định | E46: =300000*2 -> 600000 | F46: =E46*12 -> 7200000 | G46: =F46*(1+5%) -> 7560000 | H46: =G46*(1+5%) -> 7938000 | I46: =H46*(1+5%) -> 8334900 | J46: =I46*(1+5%) -> 8751645 | O46: Chi phí đầu tư ban đầu
B47: 8 | C47: Nước cố định | E47: =75000*2 -> 150000 | F47: =E47*12 -> 1800000 | G47: =F47*(1+3%) -> 1854000 | H47: =G47*(1+3%) -> 1909620 | I47: =H47*(1+3%) -> 1966908.6 | J47: =I47*(1+3%) -> 2025915.9 | O47: STT | P47: Khoản mục | Q47: Năm 0
B48: 9 | C48: Bảo trì, bảo dưỡng thiết bị | E48: =150000*2 -> 300000 | F48: =E48*12 -> 3600000 | G48: =F48*(1+5%) -> 3780000 | H48: =G48*(1+5%) -> 3969000 | I48: =H48*(1+5%) -> 4167450 | J48: =I48*(1+5%) -> 4375822.5 | O48: 1 | P48: Đăng ký hộ kinh doanh và chuẩn bị hợp đồng | Q48: 500000
O49: 2 | P49: Chi phí pháp lý quản lý doanh nghiệp | Q49: =E18 -> 150000
B50: Tổng | E50: =SUM(E38:E48) -> 58745000 | F50: =SUM(F38:F48) -> 704940000 | G50: =SUM(G38:G48) -> 734667600 | H50: =SUM(H38:H48) -> 765661164 | I50: =SUM(I38:I48) -> 7.9797518e+08 | J50: =SUM(J38:J48) -> 8.3166653e+08 | K50: GIẢI THÍCH BẢNG CHI PHÍ CỐ ĐỊNH | O50: 3 | P50: Chi phí trang thiết bị | Q50: =G31 -> 91182000
...

Sheet Dự toán thuế GTGT
A1: DỰ TOÁN THUẾ GTGT – PHƯƠNG PHÁP TRỰC TIẾP TRÊN DOANH THU
A2: Giả định: công ty đủ điều kiện tính trực tiếp; bán lại hàng hóa thành phẩm, không tự sản xuất | C2: Theo khoản 1 Điều 12 Luật Thuế giá trị gia tăng số 48/2024/QH15, quy định về phương pháp tính thuế GTGT trực tiếp trên doanh thu như sau:
A3: Tỷ lệ GTGT trực tiếp – phân phối hàng hóa | B3: 0.01
A4: Giảm tỷ lệ theo chính sách ưu đãi (nếu đủ điều kiện) | B4: 0
A5: Tỷ lệ GTGT thực tế áp dụng | B5: 0.01
A12: Chỉ tiêu | B12: Tháng 1 | C12: Tháng 2 | D12: Tháng 3 | E12: Tháng 4 | F12: Tháng 5 | G12: Tháng 6 | H12: Tháng 7 | I12: Tháng 8 | J12: Tháng 9 | K12: Tháng 10 | L12: Tháng 11 | M12: Tháng 12 | N12: Năm 1 | O12: Năm 2 | P12: Năm 3 | Q12: Năm 4 | R12: Năm 5
A13: Doanh thu bán hàng (đã gồm GTGT theo trực tiếp) | B13: ='Dự toán báo cáo thu nhập'!B3 -> 61200000 | C13: ='Dự toán báo cáo thu nhập'!C3 -> 66300000 | D13: ='Dự toán báo cáo thu nhập'!D3 -> 66300000 | E13: ='Dự toán báo cáo thu nhập'!E3 -> 66300000 | F13: ='Dự toán báo cáo thu nhập'!F3 -> 66300000 | G13: ='Dự toán báo cáo thu nhập'!G3 -> 66300000 | H13: ='Dự toán báo cáo thu nhập'!H3 -> 66300000 | I13: ='Dự toán báo cáo thu nhập'!I3 -> 66300000 | ... R13: ='Dự toán báo cáo thu nhập'!R3 -> 1.2888894e+09
A14: Giảm trừ bán hàng / khuyến mãi | B14: ='Dự toán báo cáo thu nhập'!B4 -> 2000000 | C14: 0 | D14: 0 | E14: 0 | F14: 0 | G14: 0 | H14: 0 | I14: 0 | J14: 0 | K14: 0 | L14: 0 | M14: 0 | N14: ='Dự toán báo cáo thu nhập'!N4 -> 2000000 | O14: 0 | P14: 0 | Q14: 0 | R14: 0
A15: Doanh thu tính thuế GTGT | B15: =MAX(0,B13-B14) -> 59200000 | C15: =MAX(0,C13-C14) -> 66300000 | D15: =MAX(0,D13-D14) -> 66300000 | E15: =MAX(0,E13-E14) -> 66300000 | F15: =MAX(0,F13-F14) -> 66300000 | G15: =MAX(0,G13-G14) -> 66300000 | H15: =MAX(0,H13-H14) -> 66300000 | I15: =MAX(0,I13-I14) -> 66300000 | ... R15: =MAX(0,R13-R14) -> 1.2888894e+09
A16: Tỷ lệ GTGT trực tiếp | B16: 0.01 | C16: 0.01 | D16: 0.01 | E16: 0.01 | F16: 0.01 | G16: 0.01 | H16: 0.01 | I16: 0.01 | J16: 0.01 | K16: 0.01 | L16: 0.01 | M16: 0.01 | N16: 0.01 | O16: 0.01 | P16: 0.01 | Q16: 0.01 | R16: 0.01
A17: Thuế GTGT phải nộp | B17: =B15*B16 -> 592000 | C17: =C15*C16 -> 663000 | D17: =D15*D16 -> 663000 | E17: =E15*E16 -> 663000 | F17: =F15*F16 -> 663000 | G17: =G15*G16 -> 663000 | H17: =H15*H16 -> 663000 | I17: =I15*I16 -> 663000 | ... R17: =R15*R16 -> 12888894
A18: Doanh thu thuần sau GTGT | B18: =B15-B17 -> 58608000 | C18: =C15-C17 -> 65637000 | D18: =D15-D17 -> 65637000 | E18: =E15-E17 -> 65637000 | F18: =F15-F17 -> 65637000 | G18: =G15-G17 -> 65637000 | H18: =H15-H17 -> 65637000 | I18: =I15-I17 -> 65637000 | ... R18: =R15-R17 -> 1.2760005e+09
A19: Thuế GTGT đầu vào khấu trừ | B19: 0 | C19: 0 | D19: 0 | E19: 0 | F19: 0 | G19: 0 | H19: 0 | I19: 0 | J19: 0 | K19: 0 | L19: 0 | M19: 0 | N19: 0 | O19: 0 | P19: 0 | Q19: 0 | R19: 0

Sheet Dự toán báo cáo thu nhập
A1: DỰ TOÁN BÁO CÁO THU NHẬP
B2: Tháng 1 | C2: Tháng 2 | D2: Tháng 3 | E2: Tháng 4 | F2: Tháng 5 | G2: Tháng 6 | H2: Tháng 7 | I2: Tháng 8 | J2: Tháng 9 | K2: Tháng 10 | L2: Tháng 11 | M2: Tháng 12 | N2: Năm 1 | O2: Năm 2 | P2: Năm 3 | Q2: Năm 4 | R2: Năm 5 | T2: Tỷ lệ thuế TNDN | U2: Tăng lương/năm
A3: Doanh thu | B3: ='Giả định doanh thu'!C39 -> 61200000 | C3: ='Giả định doanh thu'!D39 -> 66300000 | D3: ='Giả định doanh thu'!E39 -> 66300000 | E3: ='Giả định doanh thu'!F39 -> 66300000 | F3: ='Giả định doanh thu'!G39 -> 66300000 | G3: ='Giả định doanh thu'!H39 -> 66300000 | H3: ='Giả định doanh thu'!I41 -> 66300000 | I3: ='Giả định doanh thu'!J41 -> 66300000 | J3: ='Giả định doanh thu'!K41 -> 66300000 | K3: ='Giả định doanh thu'!L41 -> 66300000 | L3: ='Giả định doanh thu'!M41 -> 66300000 | M3: ='Giả định doanh thu'!N41 -> 66300000 | N3: ='Giả định doanh thu'!O41 -> 790500000 | O3: ='Giả định doanh thu'!D58 -> 8.93265e+08 | P3: ='Giả định doanh thu'!E58 -> 1.0093894e+09 | Q3: ='Giả định doanh thu'!F58 -> 1.1406101e+09 | R3: ='Giả định doanh thu'!G58 -> 1.2888894e+09 | T3: 0.15 | U3: 0.05
A4: (Các khoản giảm trừ doanh thu) | B4: ='Giả định doanh thu'!C40 -> 2000000 | C4: 0 | D4: 0 | E4: 0 | F4: 0 | G4: 0 | H4: 0 | I4: 0 | J4: 0 | K4: 0 | L4: 0 | M4: 0 | N4: ='Giả định doanh thu'!C59 -> 2000000 | O4: 0 | P4: 0 | Q4: 0 | R4: 0
A5: Doanh thu thuần | B5: =B3-B4-'Dự toán thuế GTGT'!B17 -> 58608000 | C5: =C3-C4-'Dự toán thuế GTGT'!C17 -> 65637000 | D5: =D3-D4-'Dự toán thuế GTGT'!D17 -> 65637000 | E5: =E3-E4-'Dự toán thuế GTGT'!E17 -> 65637000 | F5: =F3-F4-'Dự toán thuế GTGT'!F17 -> 65637000 | G5: =G3-G4-'Dự toán thuế GTGT'!G17 -> 65637000 | H5: =H3-H4-'Dự toán thuế GTGT'!H17 -> 65637000 | I5: =I3-I4-'Dự toán thuế GTGT'!I17 -> 65637000 | ... R5: =R3-R4-'Dự toán thuế GTGT'!R17 -> 1.2760005e+09
A6: (Giá vốn hàng bán) | B6: ='Giả định doanh thu'!C48 -> 15420000 | C6: ='Giả định doanh thu'!D48 -> 16705000 | D6: ='Giả định doanh thu'!E48 -> 16705000 | E6: ='Giả định doanh thu'!F48 -> 16705000 | F6: ='Giả định doanh thu'!G48 -> 16705000 | G6: ='Giả định doanh thu'!H48 -> 16705000 | H6: ='Giả định doanh thu'!I48 -> 16705000 | I6: ='Giả định doanh thu'!J48 -> 16705000 | ... N6: ='Giả định doanh thu'!O48 -> 199175000 | O6: ='Giả định doanh thu'!D67 -> 225665275 | P6: ='Giả định doanh thu'!E67 -> 2.482318e+08 | Q6: ='Giả định doanh thu'!F67 -> 2.7305498e+08 | R6: ='Giả định doanh thu'!G67 -> 3.0036048e+08
A7: (Hao hụt khi chiết rót) (3% giá vốn) | B7: =B6*3% -> 462600 | C7: =C6*3% -> 501150 | D7: =D6*3% -> 501150 | E7: =E6*3% -> 501150 | F7: =F6*3% -> 501150 | G7: =G6*3% -> 501150 | H7: =H6*3% -> 501150 | I7: =I6*3% -> 501150 | ... R7: =R6*3% -> 9010814.4
A8: Lợi nhuận gộp | B8: =B5-SUM(B6:B7) -> 42725400 | C8: =C5-SUM(C6:C7) -> 48430850 | D8: =D5-SUM(D6:D7) -> 48430850 | E8: =E5-SUM(E6:E7) -> 48430850 | F8: =F5-SUM(F6:F7) -> 48430850 | G8: =G5-SUM(G6:G7) -> 48430850 | H8: =H5-SUM(H6:H7) -> 48430850 | I8: =I5-SUM(I6:I7) -> 48430850 | ... R8: =R5-SUM(R6:R7) -> 9.666292e+08
A9: Chi phí chung
A10: Lương nhân sự | B10: ='Giả định chi phí'!F11 -> 45695000 | C10: =B10 -> 45695000 | D10: =C10 -> 45695000 | E10: =D10 -> 45695000 | F10: =E10 -> 45695000 | G10: =F10 -> 45695000 | H10: =G10 -> 45695000 | I10: =H10 -> 45695000 | J10: =I10 -> 45695000 | ... M10: =L10 -> 45695000 | N10: =SUM('Giả định chi phí'!F38:F42) -> 548340000 | O10: =SUM('Giả định chi phí'!G38:G42) -> 570273600 | P10: =SUM('Giả định chi phí'!H38:H42) -> 593084544 | Q10: =SUM('Giả định chi phí'!I38:I42) -> 6.1680793e+08 | R10: =SUM('Giả định chi phí'!J38:J42) -> 6.4148024e+08
A11: Thuê mặt bằng (2 trạm) | B11: ='Giả định chi phí'!E44 -> 12000000 | C11: ='Giả định chi phí'!E44 -> 12000000 | D11: ='Giả định chi phí'!E44 -> 12000000 | E11: ='Giả định chi phí'!E44 -> 12000000 | F11: ='Giả định chi phí'!E44 -> 12000000 | G11: ='Giả định chi phí'!E44 -> 12000000 | H11: ='Giả định chi phí'!E44 -> 12000000 | I11: ='Giả định chi phí'!E44 -> 12000000 | J11: ='Giả định chi phí'!E44 -> 12000000 | K11: ='Giả định chi phí'!E44 -> 12000000 | L11: ='Giả định chi phí'!E44 -> 12000000 | M11: ='Giả định chi phí'!E44 -> 12000000 | N11: ='Giả định chi phí'!F44 -> 144000000 | O11: ='Giả định chi phí'!G44 -> 151200000 | P11: ='Giả định chi phí'!H44 -> 158760000 | Q11: ='Giả định chi phí'!I44 -> 166698000 | R11: ='Giả định chi phí'!J44 -> 175032900
A12: Chi phí điện | B12: ='Giả định chi phí'!E46 -> 600000 | C12: ='Giả định chi phí'!E46 -> 600000 | D12: ='Giả định chi phí'!E46 -> 600000 | E12: ='Giả định chi phí'!E46 -> 600000 | F12: ='Giả định chi phí'!E46 -> 600000 | G12: ='Giả định chi phí'!E46 -> 600000 | H12: ='Giả định chi phí'!E46 -> 600000 | I12: ='Giả định chi phí'!E46 -> 600000 | J12: ='Giả định chi phí'!E46 -> 600000 | K12: ='Giả định chi phí'!E46 -> 600000 | L12: ='Giả định chi phí'!E46 -> 600000 | M12: ='Giả định chi phí'!E46 -> 600000 | N12: ='Giả định chi phí'!F46 -> 7200000 | O12: ='Giả định chi phí'!G46 -> 7560000 | P12: ='Giả định chi phí'!H46 -> 7938000 | Q12: ='Giả định chi phí'!I46 -> 8334900 | R12: ='Giả định chi phí'!J46 -> 8751645
A13: Chi phí nước | B13: ='Giả định chi phí'!E47 -> 150000 | C13: ='Giả định chi phí'!E47 -> 150000 | D13: ='Giả định chi phí'!E47 -> 150000 | E13: ='Giả định chi phí'!E47 -> 150000 | F13: ='Giả định chi phí'!E47 -> 150000 | G13: ='Giả định chi phí'!E47 -> 150000 | H13: ='Giả định chi phí'!E47 -> 150000 | I13: ='Giả định chi phí'!E47 -> 150000 | J13: ='Giả định chi phí'!E47 -> 150000 | K13: ='Giả định chi phí'!E47 -> 150000 | L13: ='Giả định chi phí'!E47 -> 150000 | M13: ='Giả định chi phí'!E47 -> 150000 | N13: ='Giả định chi phí'!F47 -> 1800000 | O13: ='Giả định chi phí'!G47 -> 1854000 | P13: ='Giả định chi phí'!H47 -> 1909620 | Q13: ='Giả định chi phí'!I47 -> 1966908.6 | R13: ='Giả định chi phí'!J47 -> 2025915.9
A14: Bảo trì, bảo dưỡng thiết bị | B14: ='Giả định chi phí'!E48 -> 300000 | C14: ='Giả định chi phí'!E48 -> 300000 | D14: ='Giả định chi phí'!E48 -> 300000 | E14: ='Giả định chi phí'!E48 -> 300000 | F14: ='Giả định chi phí'!E48 -> 300000 | G14: ='Giả định chi phí'!E48 -> 300000 | H14: ='Giả định chi phí'!E48 -> 300000 | I14: ='Giả định chi phí'!E48 -> 300000 | J14: ='Giả định chi phí'!E48 -> 300000 | K14: ='Giả định chi phí'!E48 -> 300000 | L14: ='Giả định chi phí'!E48 -> 300000 | M14: ='Giả định chi phí'!E48 -> 300000 | N14: ='Giả định chi phí'!F48 -> 3600000 | O14: ='Giả định chi phí'!G48 -> 3780000 | P14: ='Giả định chi phí'!H48 -> 3969000 | Q14: ='Giả định chi phí'!I48 -> 4167450 | R14: ='Giả định chi phí'!J48 -> 4375822.5
A15: Vật tư vệ sinh | B15: ='Giả định chi phí'!D57 -> 500000 | C15: ='Giả định chi phí'!E57 -> 500000 | D15: ='Giả định chi phí'!E57 -> 500000 | E15: ='Giả định chi phí'!E57 -> 500000 | F15: ='Giả định chi phí'!E57 -> 500000 | G15: ='Giả định chi phí'!E57 -> 500000 | H15: ='Giả định chi phí'!E57 -> 500000 | I15: ='Giả định chi phí'!E57 -> 500000 | J15: ='Giả định chi phí'!E57 -> 500000 | K15: ='Giả định chi phí'!E57 -> 500000 | L15: ='Giả định chi phí'!E57 -> 500000 | M15: ='Giả định chi phí'!E57 -> 500000 | N15: ='Giả định chi phí'!F57 -> 6000000 | O15: ='Giả định chi phí'!G57 -> 6600000 | P15: ='Giả định chi phí'!H57 -> 7260000 | Q15: ='Giả định chi phí'!I57 -> 7986000 | R15: ='Giả định chi phí'!J57 -> 8784600
A16: Chi phí quảng cáo Facebook/TikTok | B16: ='Giả định chi phí'!G72/12 -> 208333.33 | C16: ='Giả định chi phí'!G72/12 -> 208333.33 | D16: ='Giả định chi phí'!G72/12 -> 208333.33 | E16: ='Giả định chi phí'!G72/12 -> 208333.33 | F16: ='Giả định chi phí'!G72/12 -> 208333.33 | G16: ='Giả định chi phí'!G72/12 -> 208333.33 | H16: ='Giả định chi phí'!G72/12 -> 208333.33 | I16: ='Giả định chi phí'!G72/12 -> 208333.33 | J16: ='Giả định chi phí'!G72/12 -> 208333.33 | K16: ='Giả định chi phí'!G72/12 -> 208333.33 | L16: ='Giả định chi phí'!G72/12 -> 208333.33 | M16: ='Giả định chi phí'!G72/12 -> 208333.33 | N16: ='Giả định chi phí'!G72 -> 2500000 | O16: ='Giả định chi phí'!I72 -> 3500000 | P16: ='Giả định chi phí'!K72 -> 4500000 | Q16: ='Giả định chi phí'!M72 -> 5000000 | R16: ='Giả định chi phí'!O72 -> 5500000
A17: Chi phí sản xuất nội dung | B17: ='Giả định chi phí'!G73/12 -> 291666.67 | C17: ='Giả định chi phí'!G73/12 -> 291666.67 | D17: ='Giả định chi phí'!G73/12 -> 291666.67 | E17: ='Giả định chi phí'!G73/12 -> 291666.67 | F17: ='Giả định chi phí'!G73/12 -> 291666.67 | G17: ='Giả định chi phí'!G73/12 -> 291666.67 | H17: ='Giả định chi phí'!G73/12 -> 291666.67 | I17: ='Giả định chi phí'!G73/12 -> 291666.67 | J17: ='Giả định chi phí'!G73/12 -> 291666.67 | K17: ='Giả định chi phí'!G73/12 -> 291666.67 | L17: ='Giả định chi phí'!G73/12 -> 291666.67 | M17: ='Giả định chi phí'!G73/12 -> 291666.67 | N17: ='Giả định chi phí'!G73 -> 3500000 | O17: ='Giả định chi phí'!I73 -> 4000000 | P17: ='Giả định chi phí'!K73 -> 4500000 | Q17: ='Giả định chi phí'!M73 -> 5000000 | R17: ='Giả định chi phí'!O73 -> 5000000
A18: Chi phí khấu hao TSCĐ | B18: ='Giả định chi phí'!F66/12 -> 1519700 | C18: ='Giả định chi phí'!G66/12 -> 1519700 | D18: ='Giả định chi phí'!H66/12 -> 1519700 | E18: ='Giả định chi phí'!I66/12 -> 1519700 | F18: ='Giả định chi phí'!F66/12 -> 1519700 | G18: ='Giả định chi phí'!F66/12 -> 1519700 | H18: ='Giả định chi phí'!F66/12 -> 1519700 | I18: ='Giả định chi phí'!F66/12 -> 1519700 | J18: ='Giả định chi phí'!F66/12 -> 1519700 | K18: ='Giả định chi phí'!F66/12 -> 1519700 | L18: ='Giả định chi phí'!G66/12 -> 1519700 | M18: ='Giả định chi phí'!G66/12 -> 1519700 | N18: ='Giả định chi phí'!F66 -> 18236400 | O18: ='Giả định chi phí'!G66 -> 18236400 | P18: ='Giả định chi phí'!H66 -> 18236400 | Q18: ='Giả định chi phí'!I66 -> 18236400 | R18: ='Giả định chi phí'!J66 -> 18236400
A19: Chi phí khác (chưa có giả định) | B19: =0 -> 0 | C19: =0 -> 0 | D19: =0 -> 0 | E19: =0 -> 0 | F19: =0 -> 0 | G19: =0 -> 0 | H19: =0 -> 0 | I19: =0 -> 0 | ... R19: =0 -> 0
A20: Tổng chi phí nhân sự | B20: =B10 -> 45695000 | C20: =C10 -> 45695000 | D20: =D10 -> 45695000 | E20: =E10 -> 45695000 | F20: =F10 -> 45695000 | G20: =G10 -> 45695000 | H20: =H10 -> 45695000 | I20: =I10 -> 45695000 | ... R20: =R10 -> 6.4148024e+08
A21: Tổng chi phí mặt bằng và vận hành | B21: =SUM(B11:B15) -> 13550000 | C21: =SUM(C11:C15) -> 13550000 | D21: =SUM(D11:D15) -> 13550000 | E21: =SUM(E11:E15) -> 13550000 | F21: =SUM(F11:F15) -> 13550000 | G21: =SUM(G11:G15) -> 13550000 | H21: =SUM(H11:H15) -> 13550000 | I21: =SUM(I11:I15) -> 13550000 | ... R21: =SUM(R11:R15) -> 1.9897088e+08
A22: Tổng chi phí marketing | B22: =SUM(B16:B17) -> 500000 | C22: =SUM(C16:C17) -> 500000 | D22: =SUM(D16:D17) -> 500000 | E22: =SUM(E16:E17) -> 500000 | F22: =SUM(F16:F17) -> 500000 | G22: =SUM(G16:G17) -> 500000 | H22: =SUM(H16:H17) -> 500000 | I22: =SUM(I16:I17) -> 500000 | ... R22: =SUM(R16:R17) -> 10500000
A23: Tổng chi phí khấu hao và khác | B23: =B18 -> 1519700 | C23: =C18 -> 1519700 | D23: =D18 -> 1519700 | E23: =E18 -> 1519700 | F23: =F18 -> 1519700 | G23: =G18 -> 1519700 | H23: =H18 -> 1519700 | I23: =I18 -> 1519700 | ... R23: =R18 -> 18236400
A24: Tổng chi phí hoạt động | B24: =SUM(B20:B23) -> 61264700 | C24: =SUM(C20:C23) -> 61264700 | D24: =SUM(D20:D23) -> 61264700 | E24: =SUM(E20:E23) -> 61264700 | F24: =SUM(F20:F23) -> 61264700 | G24: =SUM(G20:G23) -> 61264700 | H24: =SUM(H20:H23) -> 61264700 | I24: =SUM(I20:I23) -> 61264700 | ... R24: =SUM(R20:R23) -> 8.6918753e+08
A25: Lợi nhuận trước thuế | B25: =B8-B24 -> -18539300 | C25: =C8-C24 -> -12833850 | D25: =D8-D24 -> -12833850 | E25: =E8-E24 -> -12833850 | F25: =F8-F24 -> -12833850 | G25: =G8-G24 -> -12833850 | H25: =H8-H24 -> -12833850 | I25: =I8-I24 -> -12833850 | ... R25: =R8-R24 -> 97441673
A26: Thuế thu nhập doanh nghiệp (xét miễn 3 năm đầu) | B26: =IF(B25>0,B25*$T$3,0) -> 0 | C26: =IF(C25>0,C25*$T$3,0) -> 0 | D26: =IF(D25>0,D25*$T$3,0) -> 0 | E26: =IF(E25>0,E25*$T$3,0) -> 0 | F26: =IF(F25>0,F25*$T$3,0) -> 0 | G26: =IF(G25>0,G25*$T$3,0) -> 0 | H26: =IF(H25>0,H25*$T$3,0) -> 0 | I26: =IF(I25>0,I25*$T$3,0) -> 0 | ... R26: =IF(R25>0,R25*$T$3,0) -> 14616251
A27: Lợi nhuận ròng (LNST) | B27: =B25-B26 -> -18539300 | C27: =C25-C26 -> -12833850 | D27: =D25-D26 -> -12833850 | E27: =E25-E26 -> -12833850 | F27: =F25-F26 -> -12833850 | G27: =G25-G26 -> -12833850 | H27: =H25-H26 -> -12833850 | I27: =I25-I26 -> -12833850 | ... R27: =R25-R26 -> 82825422
A29: Chú thích:
A30: 1. Điều kiện áp dụng chính sách miễn Thuế TNDN: | C30: https://chinhsachonline.chinhphu.vn/dieu-kien-ap-dung-chinh-sach-mien-thue-thu-nhap-doanh-nghiep-85100.htm
A31: 2. Theo Khoản 2 Điều 11 – Thuế suất TNDN: | C31: https://datafiles.chinhphu.vn/cpp/files/vbpq/2025/7/67qh.signed.pdf

Sheet Dự toán BCĐKT
A1: DỰ TOÁN BẢNG CÂN ĐỐI KẾ TOÁN
A2: Ký hiệu và công thức tính | C2: Năm 0 | D2: Tháng 1 | E2: Tháng 2 | F2: Tháng 3 | G2: Tháng 4 | H2: Tháng 5 | I2: Tháng 6 | J2: Tháng 7 | K2: Tháng 8 | L2: Tháng 9 | M2: Tháng 10 | N2: Tháng 11 | O2: Tháng 12 | P2: Năm 1 | Q2: Năm 2 | R2: Năm 3 | S2: Năm 4 | T2: Năm 5
A3: TÀI SẢN
A4: A. TÀI SẢN NGẮN HẠN
A5: Tiền mặt cần thiết | B5: -1 | C5: =D5 -> 17646440 | D5: =('Dự toán báo cáo thu nhập'!B6+'Dự toán báo cáo thu nhập'!B7+'Dự toán báo cáo thu nhập'!B24-'Dự toán báo cáo thu nhập'!B23)/$C$35*$C$34 -> 17646440 | E5: =('Dự toán báo cáo thu nhập'!C6+'Dự toán báo cáo thu nhập'!C7+'Dự toán báo cáo thu nhập'!C24-'Dự toán báo cáo thu nhập'!C23)/$C$35*$C$34 -> 17955268 | F5: =('Dự toán báo cáo thu nhập'!D6+'Dự toán báo cáo thu nhập'!D7+'Dự toán báo cáo thu nhập'!D24-'Dự toán báo cáo thu nhập'!D23)/$C$35*$C$34 -> 17955268 | G5: =('Dự toán báo cáo thu nhập'!E6+'Dự toán báo cáo thu nhập'!E7+'Dự toán báo cáo thu nhập'!E24-'Dự toán báo cáo thu nhập'!E23)/$C$35*$C$34 -> 17955268 | H5: =('Dự toán báo cáo thu nhập'!F6+'Dự toán báo cáo thu nhập'!F7+'Dự toán báo cáo thu nhập'!F24-'Dự toán báo cáo thu nhập'!F23)/$C$35*$C$34 -> 17955268 | I5: =('Dự toán báo cáo thu nhập'!G6+'Dự toán báo cáo thu nhập'!G7+'Dự toán báo cáo thu nhập'!G24-'Dự toán báo cáo thu nhập'!G23)/$C$35*$C$34 -> 17955268 | J5: =('Dự toán báo cáo thu nhập'!H6+'Dự toán báo cáo thu nhập'!H7+'Dự toán báo cáo thu nhập'!H24-'Dự toán báo cáo thu nhập'!H23)/$C$35*$C$34 -> 17955268 | K5: =('Dự toán báo cáo thu nhập'!I6+'Dự toán báo cáo thu nhập'!I7+'Dự toán báo cáo thu nhập'!I24-'Dự toán báo cáo thu nhập'!I23)/$C$35*$C$34 -> 17955268 | ... O5: =('Dự toán báo cáo thu nhập'!M6+'Dự toán báo cáo thu nhập'!M7+'Dự toán báo cáo thu nhập'!M24-'Dự toán báo cáo thu nhập'!M23)/$C$35*$C$34 -> 17955268 | P5: =O5 -> 17955268 | Q5: =('Dự toán báo cáo thu nhập'!O6+'Dự toán báo cáo thu nhập'!O7+'Dự toán báo cáo thu nhập'!O24-'Dự toán báo cáo thu nhập'!O23)/$C$36*$C$34 -> 19078944 | R5: =('Dự toán báo cáo thu nhập'!P6+'Dự toán báo cáo thu nhập'!P7+'Dự toán báo cáo thu nhập'!P24-'Dự toán báo cáo thu nhập'!P23)/$C$36*$C$34 -> 20175554 | S5: =('Dự toán báo cáo thu nhập'!Q6+'Dự toán báo cáo thu nhập'!Q7+'Dự toán báo cáo thu nhập'!Q24-'Dự toán báo cáo thu nhập'!Q23)/$C$36*$C$34 -> 21334596 | T5: =('Dự toán báo cáo thu nhập'!R6+'Dự toán báo cáo thu nhập'!R7+'Dự toán báo cáo thu nhập'!R24-'Dự toán báo cáo thu nhập'!R23)/$C$36*$C$34 -> 22561825
A6: Tiền mặt thặng dư | B6: (2)=(18)-(1)-(3)-(4)-(8) | C6: =C27-C5-C7-C8-C13 -> 140521560 | D6: =D27-D5-D7-D8-D13 -> 1.7062159e+08 | E6: =E27-E5-E7-E8-E13 -> 158972890 | F6: =F27-F5-F7-F8-F13 -> 147658740 | G6: =G27-G5-G7-G8-G13 -> 136344590 | H6: =H27-H5-H7-H8-H13 -> 125030440 | I6: =I27-I5-I7-I8-I13 -> 113716290 | J6: =J27-J5-J7-J8-J13 -> 102402140 | ... T6: =T27-T5-T7-T8-T13 -> 1.9496508e+08
A7: Khoản phải thu | B7: -3 | C7: 0 | D7: =('Dự toán báo cáo thu nhập'!B3-'Dự toán báo cáo thu nhập'!B4)/$C$35*$C$31 -> 3946666.7 | E7: =('Dự toán báo cáo thu nhập'!C3-'Dự toán báo cáo thu nhập'!C4)/$C$35*$C$31 -> 4420000 | F7: =('Dự toán báo cáo thu nhập'!D3-'Dự toán báo cáo thu nhập'!D4)/$C$35*$C$31 -> 4420000 | G7: =('Dự toán báo cáo thu nhập'!E3-'Dự toán báo cáo thu nhập'!E4)/$C$35*$C$31 -> 4420000 | H7: =('Dự toán báo cáo thu nhập'!F3-'Dự toán báo cáo thu nhập'!F4)/$C$35*$C$31 -> 4420000 | I7: =('Dự toán báo cáo thu nhập'!G3-'Dự toán báo cáo thu nhập'!G4)/$C$35*$C$31 -> 4420000 | J7: =('Dự toán báo cáo thu nhập'!H3-'Dự toán báo cáo thu nhập'!H4)/$C$35*$C$31 -> 4420000 | K7: =('Dự toán báo cáo thu nhập'!I3-'Dự toán báo cáo thu nhập'!I4)/$C$35*$C$31 -> 4420000 | ... O7: =('Dự toán báo cáo thu nhập'!M3-'Dự toán báo cáo thu nhập'!M4)/$C$35*$C$31 -> 4420000 | P7: =O7 -> 4420000 | Q7: =('Dự toán báo cáo thu nhập'!O3-'Dự toán báo cáo thu nhập'!O4)/$C$36*$C$31 -> 4962583.3 | R7: =('Dự toán báo cáo thu nhập'!P3-'Dự toán báo cáo thu nhập'!P4)/$C$36*$C$31 -> 5607719.2 | S7: =('Dự toán báo cáo thu nhập'!Q3-'Dự toán báo cáo thu nhập'!Q4)/$C$36*$C$31 -> 6336722.7 | T7: =('Dự toán báo cáo thu nhập'!R3-'Dự toán báo cáo thu nhập'!R4)/$C$36*$C$31 -> 7160496.6
A8: Hàng tồn kho | B8: -4 | C8: 0 | D8: ='Dự toán báo cáo thu nhập'!B6/$C$35*$C$30 -> 2570000 | E8: ='Dự toán báo cáo thu nhập'!C6/$C$35*$C$30 -> 2784166.7 | F8: ='Dự toán báo cáo thu nhập'!D6/$C$35*$C$30 -> 2784166.7 | G8: ='Dự toán báo cáo thu nhập'!E6/$C$35*$C$30 -> 2784166.7 | H8: ='Dự toán báo cáo thu nhập'!F6/$C$35*$C$30 -> 2784166.7 | I8: ='Dự toán báo cáo thu nhập'!G6/$C$35*$C$30 -> 2784166.7 | J8: ='Dự toán báo cáo thu nhập'!H6/$C$35*$C$30 -> 2784166.7 | K8: ='Dự toán báo cáo thu nhập'!I6/$C$35*$C$30 -> 2784166.7 | ... O8: ='Dự toán báo cáo thu nhập'!M6/$C$35*$C$30 -> 2784166.7 | P8: =O8 -> 2784166.7 | Q8: ='Dự toán báo cáo thu nhập'!O6/$C$36*$C$30 -> 3134239.9 | R8: ='Dự toán báo cáo thu nhập'!P6/$C$36*$C$30 -> 3447663.9 | S8: ='Dự toán báo cáo thu nhập'!Q6/$C$36*$C$30 -> 3792430.3 | T8: ='Dự toán báo cáo thu nhập'!R6/$C$36*$C$30 -> 4171673.3
A9: Tổng tài sản ngắn hạn | B9: (5)=(1)+(2)+(3)+(4) | C9: =SUM(C5:C8) -> 158168000 | D9: =SUM(D5:D8) -> 194784700 | E9: =SUM(E5:E8) -> 184132325 | F9: =SUM(F5:F8) -> 172818175 | G9: =SUM(G5:G8) -> 161504025 | H9: =SUM(H5:H8) -> 150189875 | I9: =SUM(I5:I8) -> 138875725 | J9: =SUM(J5:J8) -> 1.2756158e+08 | ... T9: =SUM(T5:T8) -> 2.2885908e+08
A10: B. TÀI SẢN DÀI HẠN
A11: Nguyên giá tài sản cố định | B11: -6 | C11: ='Giả định chi phí'!G31 -> 91182000 | D11: =C11 -> 91182000 | E11: =D11 -> 91182000 | F11: =E11 -> 91182000 | G11: =F11 -> 91182000 | H11: =G11 -> 91182000 | I11: =H11 -> 91182000 | J11: =I11 -> 91182000 | K11: =J11 -> 91182000 | ... T11: =S11 -> 91182000
A12: Trừ: Khấu hao tích lũy | B12: -7 | C12: 0 | D12: =C12-'Dự toán báo cáo thu nhập'!B18 -> -1519700 | E12: =D12-'Dự toán báo cáo thu nhập'!C18 -> -3039400 | F12: =E12-'Dự toán báo cáo thu nhập'!D18 -> -4559100 | G12: =F12-'Dự toán báo cáo thu nhập'!E18 -> -6078800 | H12: =G12-'Dự toán báo cáo thu nhập'!F18 -> -7598500 | I12: =H12-'Dự toán báo cáo thu nhập'!G18 -> -9118200 | J12: =I12-'Dự toán báo cáo thu nhập'!H18 -> -10637900 | K12: =J12-'Dự toán báo cáo thu nhập'!I18 -> -12157600 | ... O12: =N12-'Dự toán báo cáo thu nhập'!M18 -> -18236400 | P12: =C12-'Dự toán báo cáo thu nhập'!N18 -> -18236400 | Q12: =P12-'Dự toán báo cáo thu nhập'!O18 -> -36472800 | R12: =Q12-'Dự toán báo cáo thu nhập'!P18 -> -54709200 | S12: =R12-'Dự toán báo cáo thu nhập'!Q18 -> -72945600 | T12: =S12-'Dự toán báo cáo thu nhập'!R18 -> -91182000
A13: Tài sản cố định ròng | B13: (8)=(6)+(7) | C13: =C11+C12 -> 91182000 | D13: =D11+D12 -> 89662300 | E13: =E11+E12 -> 88142600 | F13: =F11+F12 -> 86622900 | G13: =G11+G12 -> 85103200 | H13: =H11+H12 -> 83583500 | I13: =I11+I12 -> 82063800 | J13: =J11+J12 -> 80544100 | ... T13: =T11+T12 -> 0
A14: TỔNG TÀI SẢN | B14: (9)=(5)+(8) | C14: =C9+C13 -> 249350000 | D14: =D9+D13 -> 284447000 | E14: =E9+E13 -> 272274925 | F14: =F9+F13 -> 259441075 | G14: =G9+G13 -> 246607225 | H14: =H9+H13 -> 233773375 | I14: =I9+I13 -> 220939525 | J14: =J9+J13 -> 208105675 | ... T14: =T9+T13 -> 2.2885908e+08
A15: NGUỒN VỐN
A16: A. NỢ
A17: Nợ ngắn hạn
A18: Khoản phải trả | B18: -10 | C18: 0 | D18: =('Dự toán báo cáo thu nhập'!B6+'Dự toán báo cáo thu nhập'!B7)/$C$35*$C$32 -> 7941300 | E18: =('Dự toán báo cáo thu nhập'!C6+'Dự toán báo cáo thu nhập'!C7)/$C$35*$C$32 -> 8603075 | F18: =('Dự toán báo cáo thu nhập'!D6+'Dự toán báo cáo thu nhập'!D7)/$C$35*$C$32 -> 8603075 | G18: =('Dự toán báo cáo thu nhập'!E6+'Dự toán báo cáo thu nhập'!E7)/$C$35*$C$32 -> 8603075 | H18: =('Dự toán báo cáo thu nhập'!F6+'Dự toán báo cáo thu nhập'!F7)/$C$35*$C$32 -> 8603075 | I18: =('Dự toán báo cáo thu nhập'!G6+'Dự toán báo cáo thu nhập'!G7)/$C$35*$C$32 -> 8603075 | J18: =('Dự toán báo cáo thu nhập'!H6+'Dự toán báo cáo thu nhập'!H7)/$C$35*$C$32 -> 8603075 | K18: =('Dự toán báo cáo thu nhập'!I6+'Dự toán báo cáo thu nhập'!I7)/$C$35*$C$32 -> 8603075 | ... O18: =('Dự toán báo cáo thu nhập'!M6+'Dự toán báo cáo thu nhập'!M7)/$C$35*$C$32 -> 8603075 | P18: =O18 -> 8603075 | Q18: =('Dự toán báo cáo thu nhập'!O6+'Dự toán báo cáo thu nhập'!O7)/$C$36*$C$32 -> 9684801.4 | R18: =('Dự toán báo cáo thu nhập'!P6+'Dự toán báo cáo thu nhập'!P7)/$C$36*$C$32 -> 10653282 | S18: =('Dự toán báo cáo thu nhập'!Q6+'Dự toán báo cáo thu nhập'!Q7)/$C$36*$C$32 -> 11718610 | T18: =('Dự toán báo cáo thu nhập'!R6+'Dự toán báo cáo thu nhập'!R7)/$C$36*$C$32 -> 12890471
A19: Tiền công và phải trả khác | B19: -11 | C19: 0 | D19: ='Dự toán báo cáo thu nhập'!B10/$C$35*$C$33 -> 45695000 | E19: ='Dự toán báo cáo thu nhập'!C10/$C$35*$C$33 -> 45695000 | F19: ='Dự toán báo cáo thu nhập'!D10/$C$35*$C$33 -> 45695000 | G19: ='Dự toán báo cáo thu nhập'!E10/$C$35*$C$33 -> 45695000 | H19: ='Dự toán báo cáo thu nhập'!F10/$C$35*$C$33 -> 45695000 | I19: ='Dự toán báo cáo thu nhập'!G10/$C$35*$C$33 -> 45695000 | J19: ='Dự toán báo cáo thu nhập'!H10/$C$35*$C$33 -> 45695000 | K19: ='Dự toán báo cáo thu nhập'!I10/$C$35*$C$33 -> 45695000 | ... O19: ='Dự toán báo cáo thu nhập'!M10/$C$35*$C$33 -> 45695000 | P19: =O19 -> 45695000 | Q19: ='Dự toán báo cáo thu nhập'!O10/$C$36*$C$33 -> 47522800 | R19: ='Dự toán báo cáo thu nhập'!P10/$C$36*$C$33 -> 49423712 | S19: ='Dự toán báo cáo thu nhập'!Q10/$C$36*$C$33 -> 51400660 | T19: ='Dự toán báo cáo thu nhập'!R10/$C$36*$C$33 -> 53456687
A20: Tổng nợ ngắn hạn | B20: (12)=(10)+(11) | C20: =C18+C19 -> 0 | D20: =D18+D19 -> 53636300 | E20: =E18+E19 -> 54298075 | F20: =F18+F19 -> 54298075 | G20: =G18+G19 -> 54298075 | H20: =H18+H19 -> 54298075 | I20: =I18+I19 -> 54298075 | J20: =J18+J19 -> 54298075 | ... T20: =T18+T19 -> 66347158
A21: Nợ dài hạn | B21: -13 | C21: =$C$38 -> 0 | D21: =$C$38 -> 0 | E21: =$C$38 -> 0 | F21: =$C$38 -> 0 | G21: =$C$38 -> 0 | H21: =$C$38 -> 0 | I21: =$C$38 -> 0 | J21: =$C$38 -> 0 | ... T21: =$C$38 -> 0
A22: Tổng nợ | B22: (14)=(12)+(13) | C22: =C20+C21 -> 0 | D22: =D20+D21 -> 53636300 | E22: =E20+E21 -> 54298075 | F22: =F20+F21 -> 54298075 | G22: =G20+G21 -> 54298075 | H22: =H20+H21 -> 54298075 | I22: =I20+I21 -> 54298075 | J22: =J20+J21 -> 54298075 | ... T22: =T20+T21 -> 66347158
A23: B. VỐN CHỦ SỞ HỮU
A24: Vốn chủ sở hữu | B24: -15 | C24: =C37 -> 250000000 | D24: =C24+D37 -> 250000000 | E24: =D24+E37 -> 250000000 | F24: =E24+F37 -> 250000000 | G24: =F24+G37 -> 250000000 | H24: =G24+H37 -> 250000000 | I24: =H24+I37 -> 250000000 | J24: =I24+J37 -> 250000000 | K24: =J24+K37 -> 250000000 | ... O24: =N24+O37 -> 250000000 | P24: =C24+P37 -> 250000000 | Q24: =P24+Q37 -> 350000000 | R24: =Q24+R37 -> 400000000 | S24: =R24+S37 -> 400000000 | T24: =S24+T37 -> 400000000
A25: Lợi nhuận giữ lại | B25: -16 | C25: =-SUM('Giả định chi phí'!Q48:Q49) -> -650000 | D25: =C25+'Dự toán báo cáo thu nhập'!B27 -> -19189300 | E25: =D25+'Dự toán báo cáo thu nhập'!C27 -> -32023150 | F25: =E25+'Dự toán báo cáo thu nhập'!D27 -> -44857000 | G25: =F25+'Dự toán báo cáo thu nhập'!E27 -> -57690850 | H25: =G25+'Dự toán báo cáo thu nhập'!F27 -> -70524700 | I25: =H25+'Dự toán báo cáo thu nhập'!G27 -> -83358550 | J25: =I25+'Dự toán báo cáo thu nhập'!H27 -> -96192400 | K25: =J25+'Dự toán báo cáo thu nhập'!I27 -> -109026250 | ... O25: =N25+'Dự toán báo cáo thu nhập'!M27 -> -160361650 | P25: =C25+'Dự toán báo cáo thu nhập'!N27 -> -160361650 | Q25: =P25+'Dự toán báo cáo thu nhập'!O27 -> -2.7546853e+08 | R25: =Q25+'Dự toán báo cáo thu nhập'!P27 -> -3.320093e+08 | S25: =R25+'Dự toán báo cáo thu nhập'!Q27 -> -3.203135e+08 | T25: =S25+'Dự toán báo cáo thu nhập'!R27 -> -2.3748808e+08
A26: Tổng vốn chủ | B26: (17)=(15)+(16) | C26: =C24+C25 -> 249350000 | D26: =D24+D25 -> 230810700 | E26: =E24+E25 -> 217976850 | F26: =F24+F25 -> 205143000 | G26: =G24+G25 -> 192309150 | H26: =H24+H25 -> 179475300 | I26: =I24+I25 -> 166641450 | J26: =J24+J25 -> 153807600 | ... T26: =T24+T25 -> 1.6251192e+08
A27: TỔNG CỘNG NGUỒN VỐN | B27: (18)=(14)+(17) | C27: =C22+C26 -> 249350000 | D27: =D22+D26 -> 284447000 | E27: =E22+E26 -> 272274925 | F27: =F22+F26 -> 259441075 | G27: =G22+G26 -> 246607225 | H27: =H22+H26 -> 233773375 | I27: =I22+I26 -> 220939525 | J27: =J22+J26 -> 208105675 | ... T27: =T22+T26 -> 2.2885908e+08
A29: GIẢ ĐỊNH DÙNG CHO DỰ TOÁN BCĐKT
A30: Số ngày tồn kho (theo giá vốn hàng bán) | C30: 5 | D30: Sheet Giả định, mục 18
A31: Số ngày phải thu (theo doanh thu sau khuyến mãi) | C31: 2 | D31: Sheet Giả định, mục 18
A32: Số ngày phải trả nhà cung cấp (giá vốn + hao hụt) | C32: 15 | D32: Sheet Giả định, mục 18
A33: Số ngày lương chưa chi trả cuối kỳ | C33: 30 | D33: Giả định bổ sung: lương tháng trả vào đầu tháng sau
A34: Số ngày chi phí bằng tiền dự trữ làm tiền mặt cần thiết | C34: 7 | D34: Giả định bổ sung: dự trữ 7 ngày chi phí
A35: Số ngày trong tháng | C35: 30 | D35: Quy ước tính toán
A36: Số ngày trong năm | C36: 360 | D36: Quy ước tính toán
A37: Vốn góp chủ sở hữu trong kỳ | B37: Sheet Giả định, mục 19 | C37: 250000000 | D37: 0 | E37: 0 | F37: 0 | G37: 0 | H37: 0 | I37: 0 | J37: 0 | K37: 0 | L37: 0 | M37: 0 | N37: 0 | O37: 0 | P37: =SUM(D37:O37) -> 0 | Q37: 100000000 | R37: 50000000 | S37: 0 | T37: 0
A38: Dư nợ vay | C38: 0 | D38: Sheet Giả định, mục 19: không vay nợ
A40: KIỂM TRA
A41: Tổng tài sản - Tổng nguồn vốn | C41: =C14-C27 -> 0 | D41: =D14-D27 -> 0 | E41: =E14-E27 -> 0 | F41: =F14-F27 -> 0 | G41: =G14-G27 -> 0 | H41: =H14-H27 -> 0 | I41: =I14-I27 -> 0 | J41: =J14-J27 -> 0 | ... T41: =T14-T27 -> 0
A42: Tiền mặt cuối kỳ theo dòng tiền (gián tiếp) | C42: =C37-C11+C25 -> 158168000 | D42: =C42+'Dự toán báo cáo thu nhập'!B27+'Dự toán báo cáo thu nhập'!B18-(D7-C7)-(D8-C8)+(D18-C18)+(D19-C19)+D37-(D11-C11) -> 1.8826803e+08 | E42: =D42+'Dự toán báo cáo thu nhập'!C27+'Dự toán báo cáo thu nhập'!C18-(E7-D7)-(E8-D8)+(E18-D18)+(E19-D19)+E37-(E11-D11) -> 1.7692816e+08 | F42: =E42+'Dự toán báo cáo thu nhập'!D27+'Dự toán báo cáo thu nhập'!D18-(F7-E7)-(F8-E8)+(F18-E18)+(F19-E19)+F37-(F11-E11) -> 1.6561401e+08 | G42: =F42+'Dự toán báo cáo thu nhập'!E27+'Dự toán báo cáo thu nhập'!E18-(G7-F7)-(G8-F8)+(G18-F18)+(G19-F19)+G37-(G11-F11) -> 1.5429986e+08 | H42: =G42+'Dự toán báo cáo thu nhập'!F27+'Dự toán báo cáo thu nhập'!F18-(H7-G7)-(H8-G8)+(H18-G18)+(H19-G19)+H37-(H11-G11) -> 1.4298571e+08 | I42: =H42+'Dự toán báo cáo thu nhập'!G27+'Dự toán báo cáo thu nhập'!G18-(I7-H7)-(I8-H8)+(I18-H18)+(I19-H19)+I37-(I11-H11) -> 1.3167156e+08 | J42: =I42+'Dự toán báo cáo thu nhập'!H27+'Dự toán báo cáo thu nhập'!H18-(J7-I7)-(J8-I8)+(J18-I18)+(J19-I19)+J37-(J11-I11) -> 1.2035741e+08 | K42: =J42+'Dự toán báo cáo thu nhập'!I27+'Dự toán báo cáo thu nhập'!I18-(K7-J7)-(K8-J8)+(K18-J18)+(K19-J19)+K37-(K11-J11) -> 1.0904326e+08 | ... O42: =N42+'Dự toán báo cáo thu nhập'!M27+'Dự toán báo cáo thu nhập'!M18-(O7-N7)-(O8-N8)+(O18-N18)+(O19-N19)+O37-(O11-N11) -> 63786658 | P42: =C42+'Dự toán báo cáo thu nhập'!N27+'Dự toán báo cáo thu nhập'!N18-(P7-C7)-(P8-C8)+(P18-C18)+(P19-C19)+P37-(P11-C11) -> 63786658 | Q42: =P42+'Dự toán báo cáo thu nhập'!O27+'Dự toán báo cáo thu nhập'!O18-(Q7-P7)-(Q8-P8)+(Q18-P18)+(Q19-P19)+Q37-(Q11-P11) -> 68933045 | R42: =Q42+'Dự toán báo cáo thu nhập'!P27+'Dự toán báo cáo thu nhập'!P18-(R7-Q7)-(R8-Q8)+(R18-Q18)+(R19-Q19)+R37-(R11-Q11) -> 82539512 | S42: =R42+'Dự toán báo cáo thu nhập'!Q27+'Dự toán báo cáo thu nhập'!Q18-(S7-R7)-(S8-R8)+(S18-R18)+(S19-R19)+S37-(S11-R11) -> 1.1444022e+08 | T42: =S42+'Dự toán báo cáo thu nhập'!R27+'Dự toán báo cáo thu nhập'!R18-(T7-S7)-(T8-S8)+(T18-S18)+(T19-S19)+T37-(T11-S11) -> 2.1752691e+08
...

Sheet Dự toán BCLCTT
A1: DỰ TOÁN BÁO CÁO LƯU CHUYỂN TIỀN TỆ
A2: Chỉ tiêu | B2: Ký hiệu và công thức | C2: Năm 0 | D2: Tháng 1 | E2: Tháng 2 | F2: Tháng 3 | G2: Tháng 4 | H2: Tháng 5 | I2: Tháng 6 | J2: Tháng 7 | K2: Tháng 8 | L2: Tháng 9 | M2: Tháng 10 | N2: Tháng 11 | O2: Tháng 12 | P2: Năm 1 | Q2: Năm 2 | R2: Năm 3 | S2: Năm 4 | T2: Năm 5
A3: DÒNG TIỀN TỪ HOẠT ĐỘNG KINH DOANH
A4: Thu nhập ròng | B4: 1 | C4: ='Dự toán BCĐKT'!C25 -> -650000 | D4: ='Dự toán báo cáo thu nhập'!B27 -> -18539300 | E4: ='Dự toán báo cáo thu nhập'!C27 -> -12833850 | F4: ='Dự toán báo cáo thu nhập'!D27 -> -12833850 | G4: ='Dự toán báo cáo thu nhập'!E27 -> -12833850 | H4: ='Dự toán báo cáo thu nhập'!F27 -> -12833850 | I4: ='Dự toán báo cáo thu nhập'!G27 -> -12833850 | J4: ='Dự toán báo cáo thu nhập'!H27 -> -12833850 | K4: ='Dự toán báo cáo thu nhập'!I27 -> -12833850 | ... T4: ='Dự toán báo cáo thu nhập'!R27 -> 82825422
A5: Khấu hao ( giá trị dương) | B5: 2 | C5: 0 | D5: ='Dự toán báo cáo thu nhập'!B18 -> 1519700 | E5: ='Dự toán báo cáo thu nhập'!C18 -> 1519700 | F5: ='Dự toán báo cáo thu nhập'!D18 -> 1519700 | G5: ='Dự toán báo cáo thu nhập'!E18 -> 1519700 | H5: ='Dự toán báo cáo thu nhập'!F18 -> 1519700 | I5: ='Dự toán báo cáo thu nhập'!G18 -> 1519700 | J5: ='Dự toán báo cáo thu nhập'!H18 -> 1519700 | K5: ='Dự toán báo cáo thu nhập'!I18 -> 1519700 | ... T5: ='Dự toán báo cáo thu nhập'!R18 -> 18236400
A6: Tăng(giảm) các khoản phải thu | B6: 3 | C6: =-'Dự toán BCĐKT'!C7 -> 0 | D6: =-('Dự toán BCĐKT'!D7-'Dự toán BCĐKT'!C7) -> -3946666.7 | E6: =-('Dự toán BCĐKT'!E7-'Dự toán BCĐKT'!D7) -> -473333.33 | F6: =-('Dự toán BCĐKT'!F7-'Dự toán BCĐKT'!E7) -> 0 | G6: =-('Dự toán BCĐKT'!G7-'Dự toán BCĐKT'!F7) -> 0 | H6: =-('Dự toán BCĐKT'!H7-'Dự toán BCĐKT'!G7) -> 0 | I6: =-('Dự toán BCĐKT'!I7-'Dự toán BCĐKT'!H7) -> 0 | J6: =-('Dự toán BCĐKT'!J7-'Dự toán BCĐKT'!I7) -> 0 | K6: =-('Dự toán BCĐKT'!K7-'Dự toán BCĐKT'!J7) -> 0 | ... O6: =-('Dự toán BCĐKT'!O7-'Dự toán BCĐKT'!N7) -> 0 | P6: =-('Dự toán BCĐKT'!P7-'Dự toán BCĐKT'!C7) -> -4420000 | Q6: =-('Dự toán BCĐKT'!Q7-'Dự toán BCĐKT'!P7) -> -542583.33 | R6: =-('Dự toán BCĐKT'!R7-'Dự toán BCĐKT'!Q7) -> -645135.83 | S6: =-('Dự toán BCĐKT'!S7-'Dự toán BCĐKT'!R7) -> -729003.49 | T6: =-('Dự toán BCĐKT'!T7-'Dự toán BCĐKT'!S7) -> -823773.95
A7: Tăng (giảm) hàng tồn kho | B7: 4 | C7: =-'Dự toán BCĐKT'!C8 -> 0 | D7: =-('Dự toán BCĐKT'!D8-'Dự toán BCĐKT'!C8) -> -2570000 | E7: =-('Dự toán BCĐKT'!E8-'Dự toán BCĐKT'!D8) -> -214166.67 | F7: =-('Dự toán BCĐKT'!F8-'Dự toán BCĐKT'!E8) -> 0 | G7: =-('Dự toán BCĐKT'!G8-'Dự toán BCĐKT'!F8) -> 0 | H7: =-('Dự toán BCĐKT'!H8-'Dự toán BCĐKT'!G8) -> 0 | I7: =-('Dự toán BCĐKT'!I8-'Dự toán BCĐKT'!H8) -> 0 | J7: =-('Dự toán BCĐKT'!J8-'Dự toán BCĐKT'!I8) -> 0 | K7: =-('Dự toán BCĐKT'!K8-'Dự toán BCĐKT'!J8) -> 0 | ... O7: =-('Dự toán BCĐKT'!O8-'Dự toán BCĐKT'!N8) -> 0 | P7: =-('Dự toán BCĐKT'!P8-'Dự toán BCĐKT'!C8) -> -2784166.7 | Q7: =-('Dự toán BCĐKT'!Q8-'Dự toán BCĐKT'!P8) -> -350073.26 | R7: =-('Dự toán BCĐKT'!R8-'Dự toán BCĐKT'!Q8) -> -313423.99 | S7: =-('Dự toán BCĐKT'!S8-'Dự toán BCĐKT'!R8) -> -344766.39 | T7: =-('Dự toán BCĐKT'!T8-'Dự toán BCĐKT'!S8) -> -379243.03
A8: Tăng (giảm) các khoản phải trả | B8: 5 | C8: ='Dự toán BCĐKT'!C18 -> 0 | D8: =('Dự toán BCĐKT'!D18-'Dự toán BCĐKT'!C18) -> 7941300 | E8: =('Dự toán BCĐKT'!E18-'Dự toán BCĐKT'!D18) -> 661775 | F8: =('Dự toán BCĐKT'!F18-'Dự toán BCĐKT'!E18) -> 0 | G8: =('Dự toán BCĐKT'!G18-'Dự toán BCĐKT'!F18) -> 0 | H8: =('Dự toán BCĐKT'!H18-'Dự toán BCĐKT'!G18) -> 0 | I8: =('Dự toán BCĐKT'!I18-'Dự toán BCĐKT'!H18) -> 0 | J8: =('Dự toán BCĐKT'!J18-'Dự toán BCĐKT'!I18) -> 0 | K8: =('Dự toán BCĐKT'!K18-'Dự toán BCĐKT'!J18) -> 0 | ... O8: =('Dự toán BCĐKT'!O18-'Dự toán BCĐKT'!N18) -> 0 | P8: =('Dự toán BCĐKT'!P18-'Dự toán BCĐKT'!C18) -> 8603075 | Q8: =('Dự toán BCĐKT'!Q18-'Dự toán BCĐKT'!P18) -> 1081726.4 | R8: =('Dự toán BCĐKT'!R18-'Dự toán BCĐKT'!Q18) -> 968480.14 | S8: =('Dự toán BCĐKT'!S18-'Dự toán BCĐKT'!R18) -> 1065328.2 | T8: =('Dự toán BCĐKT'!T18-'Dự toán BCĐKT'!S18) -> 1171861
A9: Tăng (giảm) tiền công cần trả | B9: 6 | C9: ='Dự toán BCĐKT'!C19 -> 0 | D9: =('Dự toán BCĐKT'!D19-'Dự toán BCĐKT'!C19) -> 45695000 | E9: =('Dự toán BCĐKT'!E19-'Dự toán BCĐKT'!D19) -> 0 | F9: =('Dự toán BCĐKT'!F19-'Dự toán BCĐKT'!E19) -> 0 | G9: =('Dự toán BCĐKT'!G19-'Dự toán BCĐKT'!F19) -> 0 | H9: =('Dự toán BCĐKT'!H19-'Dự toán BCĐKT'!G19) -> 0 | I9: =('Dự toán BCĐKT'!I19-'Dự toán BCĐKT'!H19) -> 0 | J9: =('Dự toán BCĐKT'!J19-'Dự toán BCĐKT'!I19) -> 0 | K9: =('Dự toán BCĐKT'!K19-'Dự toán BCĐKT'!J19) -> 0 | ... O9: =('Dự toán BCĐKT'!O19-'Dự toán BCĐKT'!N19) -> 0 | P9: =('Dự toán BCĐKT'!P19-'Dự toán BCĐKT'!C19) -> 45695000 | Q9: =('Dự toán BCĐKT'!Q19-'Dự toán BCĐKT'!P19) -> 1827800 | R9: =('Dự toán BCĐKT'!R19-'Dự toán BCĐKT'!Q19) -> 1900912 | S9: =('Dự toán BCĐKT'!S19-'Dự toán BCĐKT'!R19) -> 1976948.5 | T9: =('Dự toán BCĐKT'!T19-'Dự toán BCĐKT'!S19) -> 2056026.4
A10: Lưu chuyển tiền thuần từ hoạt động kinh doanh | B10: 7=1+2+3+4+5+6 | C10: =SUM(C4:C9) -> -650000 | D10: =SUM(D4:D9) -> 30100033 | E10: =SUM(E4:E9) -> -11339875 | F10: =SUM(F4:F9) -> -11314150 | G10: =SUM(G4:G9) -> -11314150 | H10: =SUM(H4:H9) -> -11314150 | I10: =SUM(I4:I9) -> -11314150 | J10: =SUM(J4:J9) -> -11314150 | ... T10: =SUM(T4:T9) -> 1.0308669e+08
A11: DÒNG TIỀN TỪ HOẠT ĐỘNG ĐẦU TƯ
A12: Mua sắm tài sản cố định | B12: 8 | C12: =-'Dự toán BCĐKT'!C11 -> -91182000 | D12: =-('Dự toán BCĐKT'!D11-'Dự toán BCĐKT'!C11) -> 0 | E12: =-('Dự toán BCĐKT'!E11-'Dự toán BCĐKT'!D11) -> 0 | F12: =-('Dự toán BCĐKT'!F11-'Dự toán BCĐKT'!E11) -> 0 | G12: =-('Dự toán BCĐKT'!G11-'Dự toán BCĐKT'!F11) -> 0 | H12: =-('Dự toán BCĐKT'!H11-'Dự toán BCĐKT'!G11) -> 0 | I12: =-('Dự toán BCĐKT'!I11-'Dự toán BCĐKT'!H11) -> 0 | J12: =-('Dự toán BCĐKT'!J11-'Dự toán BCĐKT'!I11) -> 0 | K12: =-('Dự toán BCĐKT'!K11-'Dự toán BCĐKT'!J11) -> 0 | ... O12: =-('Dự toán BCĐKT'!O11-'Dự toán BCĐKT'!N11) -> 0 | P12: =-('Dự toán BCĐKT'!P11-'Dự toán BCĐKT'!C11) -> 0 | Q12: =-('Dự toán BCĐKT'!Q11-'Dự toán BCĐKT'!P11) -> 0 | R12: =-('Dự toán BCĐKT'!R11-'Dự toán BCĐKT'!Q11) -> 0 | S12: =-('Dự toán BCĐKT'!S11-'Dự toán BCĐKT'!R11) -> 0 | T12: =-('Dự toán BCĐKT'!T11-'Dự toán BCĐKT'!S11) -> 0
A13: Tăng (giảm) nguyên giá TSCĐ | B13: 9 | C13: 0 | D13: 0 | E13: 0 | F13: 0 | G13: 0 | H13: 0 | I13: 0 | J13: 0 | K13: 0 | L13: 0 | M13: 0 | N13: 0 | O13: 0 | P13: 0 | Q13: 0 | R13: 0 | S13: 0 | T13: 0
A14: Lưu chuyển tiền thuần từ hoạt động đầu tư | B14: 10=8+9 | C14: =C12+C13 -> -91182000 | D14: =D12+D13 -> 0 | E14: =E12+E13 -> 0 | F14: =F12+F13 -> 0 | G14: =G12+G13 -> 0 | H14: =H12+H13 -> 0 | I14: =I12+I13 -> 0 | J14: =J12+J13 -> 0 | ... T14: =T12+T13 -> 0
A15: DÒNG TIỀN TỪ HOẠT ĐỘNG TÀI CHÍNH
A16: Tăng (giảm) nợ vay | B16: 11 | C16: ='Dự toán BCĐKT'!C21 -> 0 | D16: =('Dự toán BCĐKT'!D21-'Dự toán BCĐKT'!C21) -> 0 | E16: =('Dự toán BCĐKT'!E21-'Dự toán BCĐKT'!D21) -> 0 | F16: =('Dự toán BCĐKT'!F21-'Dự toán BCĐKT'!E21) -> 0 | G16: =('Dự toán BCĐKT'!G21-'Dự toán BCĐKT'!F21) -> 0 | H16: =('Dự toán BCĐKT'!H21-'Dự toán BCĐKT'!G21) -> 0 | I16: =('Dự toán BCĐKT'!I21-'Dự toán BCĐKT'!H21) -> 0 | J16: =('Dự toán BCĐKT'!J21-'Dự toán BCĐKT'!I21) -> 0 | K16: =('Dự toán BCĐKT'!K21-'Dự toán BCĐKT'!J21) -> 0 | ... O16: =('Dự toán BCĐKT'!O21-'Dự toán BCĐKT'!N21) -> 0 | P16: =('Dự toán BCĐKT'!P21-'Dự toán BCĐKT'!C21) -> 0 | Q16: =('Dự toán BCĐKT'!Q21-'Dự toán BCĐKT'!P21) -> 0 | R16: =('Dự toán BCĐKT'!R21-'Dự toán BCĐKT'!Q21) -> 0 | S16: =('Dự toán BCĐKT'!S21-'Dự toán BCĐKT'!R21) -> 0 | T16: =('Dự toán BCĐKT'!T21-'Dự toán BCĐKT'!S21) -> 0
